Workbook

Sheet Questionario
B1: QUESTIONÁRIO INDULTO E COMUTAÇÃO - DECRETO Nº 12.970/2025
B2: Planilha elaborada por Tatiana Abreu Miranda e Thiago Oliveira Miranda | C2: @gpsdapena | D2: https://gpsdapena.com.br/
B3: Sentenciado: | C3: Execução nº:
B4: 0 | C4: 0
B5: Unidade Prisional: | C5: 0
B7: Penas Impostas | C7: Anos | D7: Meses | E7: Dias
B8: Total de penas de crimes IMPEDITIVOS em 25/12/2025 | C8: 0 | D8: 0 | E8: 0
B9: Total de penas de crimes COM VIOLÊNCIA ou grave ameaça em 25/12/2025 | C9: 0 | D9: 0 | E9: 0
B10: Total de penas de crimes SEM VIOLÊNCIA ou grave ameaça em 25/12/2025 | C10: 0 | D10: 0 | E10: 0
B12: Total de penas impostas | C12: =Cálculo!K9 -> 0 | D12: =Cálculo!L9 -> 0 | E12: =Cálculo!M9 -> 0
B14: Pena Cumprida | C14: Anos | D14: Meses | E14: Dias
B15: Total de pena cumprida até 25/12/2025 já considerada no Sistema | C15: 5 | D15: 6 | E15: 0
B16: Total de pena cumprida até 25/12/2025 não lançada no Sistema (prisão cautelar, prisão domiciliar, prisão especial ou recolhimento domiciliar noturno, com ou sem monitoramento eletrônico) | C16: 0 | D16: 0 | E16: 0
B17: Pena cumprida dos crimes IMPEDITIVOS até 25/12/2025 | C17: =Cálculo!O15 -> 0 anos 0 meses 0 dias
B18: Pena cumprida nos crimes não impeditivos até 25/12/2025 | C18: =Cálculo!O14 -> Sem pena cumprida
B20: Pena Remanescente | C20: Anos | D20: Meses | E20: Dias
B21: Total de pena remanescente total (impeditivo e não impeditivo) em 25/12/2025 | C21: =Cálculo!O16 -> -5 anos -6 meses 0 dias
B22: Total de pena remanescente dos crimes não impeditivos em 25/12/2025 | C22: =Cálculo!O17 -> Sem pena remanescente
B24: Frações | C24: Anos | D24: Meses | E24: Dias
B25: 2/3 dos crimes IMPEDITIVOS | C25: =Cálculo!D154 -> 0 anos 0 meses 0 dias
B26: 1/5 dos crimes não impeditivos | C26: =Cálculo!D155 -> 0 anos 0 meses 0 dias
B27: 1/4 dos crimes não impeditivos | C27: =Cálculo!D156 -> 0 anos 0 meses 0 dias
B28: 1/3 dos crimes não impeditivos | C28: =Cálculo!D157 -> 0 anos 0 meses 0 dias
B29: 1/2 dos crimes não impeditivos | C29: =Cálculo!D158 -> 0 anos 0 meses 0 dias
B31: Sexo: | E31: MASCULINO
B33: Data de nascimento: | E33: 22089
B35: Reincidente em 25/12/2025? | E35: NÃO
B37: Regime prisional em 25/12/2025: | E37: FECHADO
B39: Se estava no regime semiaberto em 25/12/2025, quanto tempo de pena cumprido ininterruptamente nesse regime? (somar remição concedida no período) | C39: Anos | D39: Meses | E39: Dias
C40: 0 | D40: 0 | E40: 0
B42: Se estava no regime aberto em 25/12/2025, quanto tempo de pena cumprido no regime semiaberto e aberto somados? (somar remição concedida no período) | C42: Anos | D42: Meses | E42: Dias
C43: 0 | D43: 0 | E43: 0
B45: Sentenciado em livramento condicional em 25/12/2025? | E45: NÃO
B47: Estava em 25/12/2025 em monitoramento eletrônico, cuja liberação tenha ocorrido com fundamento na Súmula Vinculante nº 56 do STF (falta de vaga em estabelecimento penal adequado)? Se sim, há quanto tempo? | E47: NÃO
B49: Estava em 25/12/2025 inserida como pré-egressas ou egressas em programa de acompanhamento compatível com a Política de Atenção a Pessoas Egressas do Sistema Prisional? Se sim, há quanto tempo? | E49: NÃO
B51: É pessoa que tenha se submetido, no curso da execução da pena, a programas de justiça restaurativa reconhecidos pelo Poder Judiciário ou por órgãos do Poder Executivo com atribuição em matéria penitenciária, mediante atestado de conclusão do procedimento e resolução satisfatória do conflito firmada por responsável pelo programa, em conformidade com o disposto na Resolução nº 225, de 31 de maio de 2016, do Conselho Nacional de Justiça? | E51: NÃO
B53: Data da última prisão: | E53: 40537
B55: Período em liberdade supera dois anos? (analisar todos os períodos em que houver interrupção no cumprimento de pena) | E55: NÃO
B57: Falta grave cometida entre 25/12/2024 à 25/12/2025? | E57: NÃO
B59: Falta grave cometida durante toda execução de pena? | E59: NÃO
...

Sheet Cálculo
C1: PLANILHA DE CÁLCULO PARA INDULTO E COMUTAÇÃO CONFORME O DECRETO Nº 12.970/2025
H2: =IF(I20=2,IF((D6+G8+G7)<N13,"OK","NÃO"),IF((D6+E8+E7)<N13,"OK","NÃO")) -> OK
D5: 2/3 da pena | E5: 1/4 da pena | F5: 1/3 da pena | G5: 1/5 da pena | H5: 1/2 da pena | I5: 1/8 da pena | J5: 1/6 da pena | K5: Anos | L5: Meses | M5: Dias | N5: Total de Dias
C6: TOTAL DE PENAS DE CRIME IMPEDITIVO EM 25/12/2025 | D6: =N6*2/3 -> 0 | E6: =N6*1/4 -> 0 | F6: =N6*1/3 -> 0 | G6: =N6*1/5 -> 0 | H6: =N6*1/2 -> 0 | I6: =N6*1/8 -> 0 | J6: =N6*1/6 -> 0 | K6: =Questionario!C8 -> 0 | L6: =Questionario!D8 -> 0 | M6: =Questionario!E8 -> 0 | N6: =M6+(L6*30)+(K6*360) -> 0 | O6: =""&K6&" anos "&L6&" meses "&M6&" dias" -> 0 anos 0 meses 0 dias | P6: =M6+(L6*30)+(K6*360) -> 0
C7: TOTAL DE PENAS DE CRIME COM VIOLÊNCIA OU GRAVE AMEAÇA EM 25/12/2025 | D7: =N7*2/3 -> 0 | E7: =N7*1/4 -> 0 | F7: =N7*1/3 -> 0 | G7: =N7*1/5 -> 0 | H7: =N7*1/2 -> 0 | I7: =N7*1/8 -> 0 | J7: =N7*1/6 -> 0 | K7: =Questionario!C9 -> 0 | L7: =Questionario!D9 -> 0 | M7: =Questionario!E9 -> 0 | N7: =M7+(L7*30)+(K7*360) -> 0 | O7: =""&K7&" anos "&L7&" meses "&M7&" dias" -> 0 anos 0 meses 0 dias | P7: =M7+(L7*30)+(K7*360) -> 0
C8: TOTAL DE PENAS DE CRIME SEM VIOLÊNCIA OU GRAVE AMEAÇA EM 25/12/2025 | D8: =N8*2/3 -> 0 | E8: =N8*1/4 -> 0 | F8: =N8*1/3 -> 0 | G8: =N8*1/5 -> 0 | H8: =N8*1/2 -> 0 | I8: =N8*1/8 -> 0 | J8: =N8*1/6 -> 0 | K8: =Questionario!C10 -> 0 | L8: =Questionario!D10 -> 0 | M8: =Questionario!E10 -> 0 | N8: =M8+(L8*30)+(K8*360) -> 0 | O8: =""&K8&" anos "&L8&" meses "&M8&" dias" -> 0 anos 0 meses 0 dias | P8: =M8+(L8*30)+(K8*360) -> 0
C9: TOTAL DE PENAS IMPOSTAS | K9: =IF(SUM(M6:M8)<=30,IF(SUM(L6:L8)<=11,SUM(K6:K8),IF(SUM(L6:L8)<=23,SUM(K6:K8)+1,IF(SUM(L6:L8)<=35,SUM(K6:K8)+2,SUM(K6:K8)+3))), IF(SUM(M6:M8)<=60,IF(SUM(L6:L8)+1<=11,SUM(K6:K8),IF(SUM(L6:L8)+1<=23,SUM(K6:K8)+1,IF(SUM(L6:L8)+1<=35,SUM(K6:K8)+2,SUM(K6:K8)+3))), IF(SUM(M6:M8)<=90,IF(SUM(L6:L8)+2<=11,SUM(K6:K8),IF(SUM(L6:L8)+2<=23,SUM(K6:K8)+1,IF(SUM(L6:L8)+2<=35,SUM(K6:K8)+2,SUM(K6:K8)+3))), "ERRO"))) -> 0 | L9: =IF(SUM(M6:M8)<=30,(IF(SUM(L6:L8)<=11,SUM(L6:L8),IF(SUM(L6:L8)<=23,SUM(L6:L8)-12,IF(SUM(L6:L8)<=35,SUM(L6:L8)-24,SUM(L6:L8)-36)))), IF(SUM(M6:M8)<=60,(IF(SUM(L6:L8)+1<=11,SUM(L6:L8)+1,IF(SUM(L6:L8)+1<=23,SUM(L6:L8)+1-12,IF(SUM(L6:L8)+1<=35,SUM(L6:L8)+1-24,SUM(L6:L8)+1-36)))), IF(SUM(M6:M8)<=90,(IF(SUM(L6:L8)+2<=11,SUM(L6:L8)+2,IF(SUM(L6:L8)+2<=23,SUM(L6:L8)+2-12,IF(SUM(L6:L8)+2<=35,SUM(L6:L8)+2-24,SUM(L6:L8)+2-36)))),"ERRO"))) -> 0 | M9: =IF(SUM(M6:M8)<=30,SUM(M6:M8), IF(SUM(M6:M8)<=60,SUM(M6:M8)-30, IF(SUM(M6:M8)<=90,SUM(M6:M8)-60, "ERRO"))) -> 0 | N9: =SUM(N6:N8) -> 0 | O9: =""&K9&" anos "&L9&" meses "&M9&" dias" -> 0 anos 0 meses 0 dias | P9: =SUM(P6:P8) -> 0
C11: Total pena SEEU | K11: =Questionario!C15 -> 5 | L11: =Questionario!D15 -> 6 | M11: =Questionario!E15 -> 0 | N11: =M11+(L11*30)+(K11*360) -> 1980 | O11: =""&K11&" anos "&L11&" meses "&M11&" dias" -> 5 anos 6 meses 0 dias | P11: =M11+(L11*30)+(K11*360) -> 1980
C12: Total de pena não lançada no SEEU | K12: =Questionario!C16 -> 0 | L12: =Questionario!D16 -> 0 | M12: =Questionario!E16 -> 0 | N12: =M12+(L12*30)+(K12*360) -> 0 | O12: =""&K12&" anos "&L12&" meses "&M12&" dias" -> 0 anos 0 meses 0 dias | P12: =M12+(L12*30)+(K12*360) -> 0
C13: TOTAL DE PENA CUMPRIDA ATÉ 25/12/2025 | K13: =IF(SUM(M11:M12)<=30,IF(SUM(L11:L12)<=11,SUM(K11:K12),IF(SUM(L11:L12)<=23,SUM(K11:K12)+1,IF(SUM(L11:L12)<=35,SUM(K11:K12)+2,SUM(K11:K12)+3))), IF(SUM(M11:M12)<=60,IF(SUM(L11:L12)+1<=11,SUM(K11:K12),IF(SUM(L11:L12)+1<=23,SUM(K11:K12)+1,IF(SUM(L11:L12)+1<=35,SUM(K11:K12)+2,SUM(K11:K12)+3))), IF(SUM(M11:M12)<=90,IF(SUM(L11:L12)+2<=11,SUM(K11:K12),IF(SUM(L11:L12)+2<=23,SUM(K11:K12)+1,IF(SUM(L11:L12)+2<=35,SUM(K11:K12)+2,SUM(K11:K12)+3))), "ERRO"))) -> 5 | L13: =IF(SUM(M11:M12)<=30,(IF(SUM(L11:L12)<=11,SUM(L11:L12),IF(SUM(L11:L12)<=23,SUM(L11:L12)-12,IF(SUM(L11:L12)<=35,SUM(L11:L12)-24,SUM(L11:L12)-36)))), IF(SUM(M11:M12)<=60,(IF(SUM(L11:L12)+1<=11,SUM(L11:L12)+1,IF(SUM(L11:L12)+1<=23,SUM(L11:L12)+1-12,IF(SUM(L11:L12)+1<=35,SUM(L11:L12)+1-24,SUM(L11:L12)+1-36)))), IF(SUM(M11:M12)<=90,(IF(SUM(L11:L12)+2<=11,SUM(L11:L12)+2,IF(SUM(L11:L12)+2<=23,SUM(L11:L12)+2-12,IF(SUM(L11:L12)+2<=35,SUM(L11:L12)+2-24,SUM(L11:L12)+2-36)))),"ERRO"))) -> 6 | M13: =IF(SUM(M11:M12)<=30,SUM(M11:M12), IF(SUM(M11:M12)<=60,SUM(M11:M12)-30, IF(SUM(M11:M12)<=90,SUM(M11:M12)-60, "ERRO"))) -> 0 | N13: =SUM(N10:N12) -> 1980 | O13: =""&K13&" anos "&L13&" meses "&M13&" dias" -> 5 anos 6 meses 0 dias | P13: =SUM(P10:P12) -> 1980
C14: PENA CUMPRIDA DESCONTANDO OS 2/3 HEDIONDO | K14: =N14/360 -> 0 | L14: =((N14/360)-ROUNDDOWN((N14/360),0))*12 -> 0 | M14: =((((N14/360)-ROUNDDOWN((N14/360),0))*12)-ROUNDDOWN((((N14/360)-ROUNDDOWN((N14/360),0))*12),0))*30 -> 0 | N14: =IF(N13-D6>=P7+P8,P7+P8,N13-D6) -> 0 | O14: =IF(N14>0,""&ROUNDDOWN(K14,0)&" anos "&ROUNDDOWN(L14,0)&" meses "&ROUND(M14,0)&" dias","Sem pena cumprida") -> Sem pena cumprida | P14: =IF(P13-D6>=P7+P8,P7+P8,P13-D6) -> 0
C15: Pena cumprida dos crimes IMPEDITIVOS | K15: =N15/360 -> 0 | L15: =((N15/360)-ROUNDDOWN((N15/360),0))*12 -> 0 | M15: =((((N15/360)-ROUNDDOWN((N15/360),0))*12)-ROUNDDOWN((((N15/360)-ROUNDDOWN((N15/360),0))*12),0))*30 -> 0 | N15: =IF(N13<D6,N13,D6) -> 0 | O15: =""&ROUNDDOWN(K15,0)&" anos "&ROUNDDOWN(L15,0)&" meses "&ROUND(M15,0)&" dias" -> 0 anos 0 meses 0 dias | P15: =IF(P13<D6,P13,D6) -> 0
C16: PENA REMANESCENTE | K16: =N16/360 -> -5.5 | L16: =((N16/360)-ROUNDDOWN((N16/360),0))*12 -> -6 | M16: =((((N16/360)-ROUNDDOWN((N16/360),0))*12)-ROUNDDOWN((((N16/360)-ROUNDDOWN((N16/360),0))*12),0))*30 -> 0 | N16: =N9-N13 -> -1980 | O16: =""&ROUNDDOWN(K16,0)&" anos "&ROUNDDOWN(L16,0)&" meses "&ROUND(M16,0)&" dias" -> -5 anos -6 meses 0 dias | P16: =P9-P13 -> -1980
C17: PENA REMANESCENTE DESCONTANDO O HEDIONDO | K17: =N17/360 -> -5.5 | L17: =((N17/360)-ROUNDDOWN((N17/360),0))*12 -> -6 | M17: =((((N17/360)-ROUNDDOWN((N17/360),0))*12)-ROUNDDOWN((((N17/360)-ROUNDDOWN((N17/360),0))*12),0))*30 -> 0 | N17: =(N9-N6)-(N13-D6) -> -1980 | O17: =IF(N17>0,""&ROUNDDOWN(K17,0)&" anos "&ROUNDDOWN(L17,0)&" meses "&ROUND(M17,0)&" dias","Sem pena remanescente") -> Sem pena remanescente | P17: =(P9-P6)-(P13-D6) -> -1980
C18: O CONDENADO CUMPRIU 2/3 DA PENA ATÉ 25/12/2025 A PARTIR DA DATA DO CRIME IMPEDITIVO? | I18: =IF(Questionario!E113="SIM",1,IF(Questionario!E113="NÃO",2,IF(Questionario!E113="não se aplica",3,"Erro"))) -> 1
C20: REINCIDENTE? | I20: =IF(Questionario!E35="SIM",1,IF(Questionario!E35="NÃO",2,"Erro")) -> 2
C21: Sentenciado firmou acordo de colaboração premiada? | I21: =IF(Questionario!E63="SIM",1,IF(Questionario!E63="NÃO",2,"Erro")) -> 2
C22: INTEGRA OU INTEGROU FACÇÃO CRIMINOSA? | I22: =IF(Questionario!E65="SIM",1,IF(Questionario!E65="NÃO",2,"Erro")) -> 2
C23: ESTAVA EM RDD EM 25/12/2025? | I23: =IF(Questionario!E67="SIM",1,IF(Questionario!E67="NÃO",2,"Erro")) -> 2
C24: ESTAVA EM PRESÍDIO FEDERAL EM 25/12/2025? | I24: =IF(Questionario!E69="SIM",1,IF(Questionario!E69="NÃO",2,"Erro")) -> 2
C25: QUANTIDADE DE REMIÇÃO APÓS A DATA DA ÚLTIMA PRISÃO EM DIAS | I25: =Questionario!E61 -> 0
C26: Sentenciado com paraplegia, tetraplegia, monoplegia, hemiplegia, ostomia, amputação, paralisia, cegueira ou outra deficiência física que acarrete comprometimento análogo, desde que essas condições não sejam anteriores à prática do crime; infectadas pelo vírus HIV, em estágio terminal; gestantes, cuja gravidez seja considerada de alto risco; acometidas de doença grave, crônica ou altamente contagiosa, que apresentem grave limitação ambulatorial ou severa restrição para participação regular nas atividades oferecidas pela unidade prisional ou, ainda, que exijam cuidados contínuos que não possam ser adequadamente prestados no estabelecimento; ou com transtorno do espectro autista severo (grau 3) ou neurodiversas em condição análoga? | I26: =IF(Questionario!E73="SIM",1,IF(Questionario!E73="NÃO",2,"Erro")) -> 2
C27: Se estava no regime semiaberto em 25/12/2025, quanto tempo de pena cumprido ininterruptamente nesse regime? (somar remição concedida no período) | D27: Anos | E27: Meses | F27: Dias
D28: =Questionario!C40 -> 0 | E28: =Questionario!D40 -> 0 | F28: =Questionario!E40 -> 0 | I28: =F28+(E28*30)+(D28*360) -> 0
C29: Se estava no regime aberto em 25/12/2025, quanto tempo de pena cumprido no regime semiaberto e aberto somados? (somar remição concedida no período) | D29: Anos | E29: Meses | F29: Dias
D30: =Questionario!C43 -> 0 | E30: =Questionario!D43 -> 0 | F30: =Questionario!E43 -> 0 | I30: =F30+(E30*30)+(D30*360) -> 0
C31: SEXO: | I31: =IF(Questionario!E31="feminino",1,IF(Questionario!E31="masculino",2,"Erro")) -> 2
C32: É mulher gestante? | I32: =IF(Questionario!E75="SIM",1,IF(Questionario!E75="NÃO",2,"Erro")) -> 2
C33: É mulher e tem filho ou filha com até 16 anos de idade? | I33: =IF(Questionario!E77="SIM",1,IF(Questionario!E77="NÃO",2,"Erro")) -> 2
C34: É mulher e tem filho ou filha com deficiência? | I34: =IF(Questionario!E79="SIM",1,IF(Questionario!E79="NÃO",2,"Erro")) -> 2
C35: No caso de ter filho ou filha com deficiência, ele(a) necessita dos cuidados da mãe? | I35: =IF(Questionario!E81="SIM",1,IF(Questionario!E81="NÃO",2,"Erro")) -> 2
C36: É mulher e tem filho ou filha com doença crônica grave? | I36: =IF(Questionario!E83="SIM",1,IF(Questionario!E83="NÃO",2,"Erro")) -> 2
C37: No caso de ter filho ou filha com doença crônica grave, ele necessita dos cuidados da mãe? | I37: =IF(Questionario!E85="SIM",1,IF(Questionario!E85="NÃO",2,"Erro")) -> 2
C38: É mulher gestante ou que tem filho ou filha com até dezesseis anos de idade ou com doença crônica grave ou deficiência? | I38: =IF(Questionario!#REF!="SIM",1,IF(Questionario!#REF!="NÃO",2,"Erro")) -> #REF!
C39: É mulher e possui filhos de até 16 anos de idade ou de qualquer idade, se pessoa com deficiência que comprovadamente necessite de seus cuidados? | I39: =IF(Questionario!#REF!="SIM",1,IF(Questionario!#REF!="NÃO",2,"Erro")) -> #REF!
C40: É mulher e possui filho menor de 16 anos de idade ou de qualquer idade, se pessoa com deficiência ou com doença crônica grave que necessite de seus cuidados? | I40: =IF(Questionario!#REF!="SIM",1,IF(Questionario!#REF!="NÃO",2,"Erro")) -> #REF! | K40: =IF(OR(I33=1,(AND(I34=1,I35=1)),(AND(I36=1,I37=1))),"OK","NÃO") -> NÃO
C41: É homem e o único responsável pelos cuidados de filho ou filha menor de dezesseis anos de idade ou com doença crônica grave ou deficiência? | I41: =IF(Questionario!E87="SIM",1,IF(Questionario!E87="NÃO",2,"Erro")) -> 2
C42: Pessoa imprescindível aos cuidados de criança de até doze anos de idade ou com doença grave ou deficiência? | I42: =IF(Questionario!E89="SIM",1,IF(Questionario!E89="NÃO",2,"Erro")) -> 2
C43: É avó que possuam netos de até doze anos de idade ou de qualquer idade, se pessoa com deficiência, nos termos do disposto no art. 2º da Lei nº 13.146, de 6 de julho de 2015, que comprovadamente necessite de seus cuidados e esteja sob sua responsabilidade? | I43: =IF(Questionario!E91="SIM",1,IF(Questionario!E91="NÃO",2,"Erro")) -> 2
C44: Pessoas com deficiência (aquela que tem impedimento de longo prazo de natureza física, mental, intelectual ou sensorial, o qual, em interação com uma ou mais barreiras, pode obstruir sua participação plena e efetiva na sociedade em igualdade de condições com as demais pessoas) | I44: =IF(Questionario!E71="SIM",1,IF(Questionario!E71="NÃO",2,"Erro")) -> 2
...

Sheet Resultado
C3: RESULTADO INDULTO E COMUTAÇÃO - DECRETO 12.970/2025
C4: Planilha elaborada por Tatiana Abreu Miranda e Thiago Oliveira Miranda | D4: @gpsdapena | E4: https://gpsdapena.com.br/
C5: Sentenciado: | D5: Execução nº:
C6: =Questionario!B4 -> 0 | D6: =Questionario!C4 -> 0
C7: Indulto - Art. 9º, 10 e 11 | D7: Regra Geral | E7: Regra Especial (§ 2º)
C9: I - à pena privativa de liberdade não superior a oito anos, por crime praticado sem violência ou grave ameaça a pessoa, que tenham cumprido, até 25 de dezembro de 2025, um quinto da pena, se não reincidentes, ou um terço da pena, se reincidentes; | D9: =Cálculo!O75 -> Não preenche os requisitos | E9: =Cálculo!T75 -> Não preenche os requisitos
C11: II - à pena privativa de liberdade não superior a doze anos, por crime praticado sem violência ou grave ameaça a pessoa, que tenham cumprido, até 25 de dezembro de 2025, um terço da pena, se não reincidentes, ou metade da pena, se reincidentes; | D11: =Cálculo!O78 -> Não preenche os requisitos | E11: =Cálculo!T78 -> Não preenche os requisitos
C13: III - à pena privativa de liberdade não superior a quatro anos, por crime praticado com violência ou grave ameaça a pessoa, que tenham cumprido, até 25 de dezembro de 2025, um terço da pena, se não reincidentes, ou metade da pena, se reincidentes; | D13: =Cálculo!O81 -> Não preenche os requisitos | E13: =Cálculo!T81 -> Não preenche os requisitos
C15: IV - à pena privativa de liberdade que, até 25 de dezembro de 2025, tenham cumprido, ininterruptamente, quinze anos da pena, se não reincidentes, ou vinte anos da pena, se reincidentes; | D15: =Cálculo!O84 -> Não preenche os requisitos | E15: =Cálculo!T84 -> Não preenche os requisitos
C17: V - à pena privativa de liberdade que, até 25 de dezembro de 2025, tenham cumprido, não ininterruptamente, vinte anos da pena, se não reincidentes, ou vinte e cinco anos da pena, se reincidentes, desde que o período em liberdade não supere dois anos; | D17: =Cálculo!O87 -> Não preenche os requisitos | E17: =Cálculo!T87 -> Não preenche os requisitos
C19: VI - à pena privativa de liberdade que, até 25 de dezembro de 2025, tenham cumprido em regime semiaberto, ininterruptamente, dez anos da pena, se não reincidentes, ou quinze anos da pena, se reincidentes; | D19: =Cálculo!O90 -> Não preenche os requisitos | E19: =Cálculo!T90 -> Não preenche os requisitos
C21: VII - à pena privativa de liberdade sob o regime aberto ou substituída por pena restritiva de direitos, na forma prevista no art. 44 do Decreto-Lei nº 2.848, de 7 de dezembro de 1940 – Código Penal, ou beneficiadas com a suspensão condicional da pena, que tenham cumprido, até 25 de dezembro de 2025, um sexto da pena, se não reincidentes, ou um quinto da pena, se reincidentes; | D21: =Cálculo!O93 -> Não preenche os requisitos | E21: =Cálculo!T93 -> Não preenche os requisitos
C23: VIII - à pena privativa de liberdade que estejam em livramento condicional ou cumprindo pena em regime aberto, cujo período da pena remanescente, em 25 de dezembro de 2025, não seja superior a seis anos, se não reincidentes, ou quatro anos, se reincidentes; | D23: =Cálculo!O96 -> Não preenche os requisitos | E23: =Cálculo!T96 -> Não preenche os requisitos
C25: IX - à pena privativa de liberdade sob regime inicial aberto ou substituída por pena restritiva de direitos, ou em cumprimento de livramento condicional ou em suspensão condicional da pena que, até 25 de dezembro de 2025, estejam inseridas como pré-egressas ou egressas em programa de acompanhamento compatível com a Política de Atenção a Pessoas Egressas do Sistema Prisional, instituída pela Resolução nº 307, de 17 de dezembro de 2019, do Conselho Nacional de Justiça, por, no mínimo, dois anos, atendidas por meio de patronatos, escritórios sociais, centrais de alternativas penais ou órgãos congêneres, e que obtenham parecer favorável de aproveitamento do responsável local pelo programa de atendimento; | D25: =Cálculo!O99 -> Não preenche os requisitos | E25: =Cálculo!T99 -> Não preenche os requisitos
C27: X - à pena privativa de liberdade que, até 25 de dezembro de 2025, em regime semiaberto mediante monitoramento eletrônico, na forma prevista na Resolução nº 412, de 23 de agosto de 2021, do Conselho Nacional de Justiça, cuja liberação tenha ocorrido com fundamento na Súmula Vinculante nº 56 do Supremo Tribunal Federal e que se encontrem nessa condição há mais de três anos; | D27: =Cálculo!O102 -> Não preenche os requisitos | E27: =Cálculo!T102 -> Não preenche os requisitos
C29: XI - à pena privativa de liberdade não superior a doze anos, desde que já tenham cumprido um terço da pena, se não reincidentes, ou metade da pena, se reincidentes, em regime semiaberto ou aberto, e que tenham usufruído, até 25 de dezembro de 2025, de, no mínimo, cinco saídas temporárias previstas no art. 122 da Lei nº 7.210, de 11 de julho de 1984, ou que tenham exercido trabalho externo por, no mínimo, doze meses nos três anos anteriores, contados retroativamente a 25 de dezembro de 2025; | D29: =Cálculo!O105 -> Não preenche os requisitos | E29: =Cálculo!T105 -> Não preenche os requisitos
C31: XII - à pena privativa de liberdade não superior a doze anos, desde que já tenham cumprido um sexto da pena, se não reincidentes, ou um quinto da pena, se reincidentes, e que tenham frequentado, ou estejam frequentando, curso de ensino fundamental, médio, superior, profissionalizante ou de requalificação profissional, na forma prevista no art. 126 da Lei nº 7.210, de 11 de julho de 1984, por, no mínimo, doze meses, nos três anos anteriores, se não reincidentes, ou dezoito meses, nos cinco anos anteriores, se reincidentes, contados retroativamente a 25 de dezembro de 2025; | D31: =Cálculo!O108 -> Não preenche os requisitos | E31: Sem previsão no Decreto
C33: XIII - à pena privativa de liberdade não superior a doze anos, desde que já tenham cumprido um quinto da pena, se não reincidentes, ou um quarto da pena, se reincidentes, e tenham concluído, durante a execução da pena, curso de ensino fundamental, médio, superior ou profissionalizante, certificado por autoridade educacional local, na forma prevista no art. 126 da Lei nº 7.210, de 11 de julho de 1984, nos três anos anteriores, contados retroativamente a 25 de dezembro de 2025; | D33: =Cálculo!O111 -> Não preenche os requisitos | E33: Sem previsão no Decreto
C35: XIV - à pena privativa de liberdade por crime contra o patrimônio, cometido sem violência ou grave ameaça a pessoa, com valor do bem estimado não superior a um salário mínimo à época do fato, desde que tenham cumprido, até 25 de dezembro de 2025, três meses da pena privativa de liberdade; | D35: =Cálculo!O114 -> Não preenche os requisitos | E35: Sem previsão no Decreto
C37: XV - à pena privativa de liberdade por crime contra o patrimônio, cometido sem violência ou grave ameaça a pessoa que, até 25 de dezembro de 2025, tenham reparado o dano conforme o disposto no art. 16 ou no art. 65, caput, inciso III, alínea “b”, do Decreto-Lei nº 2.848, de 7 de dezembro de 1940 – Código Penal, excetuada a necessidade de reparação do dano nas hipóteses previstas no art. 12, § 2º, deste Decreto; | D37: =Cálculo!O117 -> Não preenche os requisitos | E37: Sem previsão no Decreto
C39: XVI - a) com paraplegia, tetraplegia, monoplegia, hemiplegia, ostomia, amputação, paralisia, cegueira ou outra deficiência física que acarrete comprometimento análogo, comprovadas por laudo emitido por médico oficial, por médico designado pelo juiz da execução ou, na falta destes, por médico autorizado pelo juiz da execução, desde que essas condições não sejam anteriores à prática do crime; b) infectadas pelo Vírus da Imunodeficiência Humana (Human Immunodeficiency Virus) – HIV, em estágio terminal, comprovado por laudo emitido por médico oficial, por médico designado pelo juiz da execução ou, na falta destes, por médico autorizado pelo juiz da execução; c) gestantes cuja gravidez seja considerada de alto risco, desde que comprovada a condição por laudo emitido por médico oficial, por médico designado pelo juiz da execução ou, na falta destes, por médico autorizado pelo juiz da execução; d) acometidas de doença grave, crônica ou altamente contagiosa, que apresentem grave limitação ambulatorial ou severa restrição para participação regular nas atividades oferecidas pela unidade prisional ou, ainda, que exijam cuidados contínuos que não possam ser adequadamente prestados no estabelecimento, comprovadas a doença e a inadequação por laudo emitido por médico oficial, por médico designado pelo juiz da execução ou, na falta destes, por médico autorizado pelo juiz da execução; ou e) com transtorno do espectro autista severo (grau 3) ou neurodiversas em condição análoga, comprovado por laudo emitido por médico oficial, por médico designado pelo juiz da execução ou, na falta destes, por médico autorizado pelo juiz da execução. | D39: =Cálculo!O120 -> Não preenche os requisitos | E39: Sem previsão no Decreto
C41: Art. 10. Sem prejuízo do disposto neste Decreto, concede-se indulto natalino especial às mulheres presas, nacionais ou migrantes, que, até 25 de dezembro de 2025, cumulativamente: | D41: =Cálculo!O123 -> Não preenche os requisitos | E41: Sem previsão no Decreto
C43: Art. 12. Concede-se o indulto coletivo às pessoas, nacionais e migrantes, condenadas a pena de multa: | D43: =Cálculo!O126 -> A analisar | E43: Sem previsão no Decreto
C46: Comutação - Art. 11 e 13 | E46: Total de Comutação
C47: Art. 11. Concede-se a comutação de pena privativa de liberdade às mulheres, nacionais e migrantes: I - na proporção de um quarto da pena, se reincidentes, quando se tratar de mulheres condenadas à pena privativa de liberdade não superior a oito anos por crime cometido sem violência ou grave ameaça a pessoa, desde que tenham cumprido um terço da pena até 25 de dezembro de 2025; | D47: =Cálculo!O129 -> Não preenche os requisitos | E47: =Cálculo!H145 -> Sem Comutação
C48: Total de pena após a Comutação: | E48: =Cálculo!M145 -> Sem Comutação
C50: Art. 11, II - na proporção de dois terços da pena, se não reincidentes, quando se tratar de mulheres condenadas por crime cometido sem violência ou grave ameaça a pessoa que tenham filho menor de dezesseis anos de idade ou de qualquer idade, se pessoa com deficiência ou com doença crônica grave que necessite de seus cuidados, desde que cumprido um quinto da pena até 25 de dezembro de 2025; e | D50: =Cálculo!O132 -> Não preenche os requisitos | E50: =Cálculo!H146 -> Sem Comutação
C51: Total de pena após a Comutação: | E51: =Cálculo!M146 -> Sem Comutação
C53: Art. 11, III - na proporção da metade da pena, se reincidentes, quando se tratar de mulheres condenadas por crime cometido sem violência ou grave ameaça a pessoa que tenha filho menor de dezesseis anos de idade ou de qualquer idade, se pessoa com deficiência ou com doença crônica grave que necessite de seus cuidados, desde que cumprido um quinto da pena até 25 de dezembro de 2025. | D53: =Cálculo!O135 -> Não preenche os requisitos | E53: =Cálculo!H147 -> Sem Comutação
C54: Total de pena após a Comutação: | E54: =Cálculo!M147 -> Sem Comutação
C56: Art. 13. Concede-se a comutação da pena remanescente na proporção de um quinto da pena às pessoas condenadas à pena privativa de liberdade que tenham cumprido, até 25 de dezembro de 2025, um quinto da pena, se não reincidentes, ou um quarto da pena, se reincidentes. | D56: =Cálculo!O138 -> Não preenche os requisitos | E56: =Cálculo!H148 -> Sem Comutação
C57: Total de pena após a Comutação: | E57: =Cálculo!M148 -> Sem Comutação
C59: Art. 13, § 4º Para as pessoas de que trata o art. 9º, § 2º, a comutação de pena prevista neste artigo será na proporção de dois terços. | D59: =Cálculo!O141 -> Não preenche os requisitos | E59: =Cálculo!H149 -> Sem Comutação
C60: Total de pena após a Comutação: | E60: =Cálculo!M149 -> Sem Comutação
C63: Observações
C64: =Questionario!B124 -> 0
C66: Notas
C67: 1- Esta planilha não dispensa o usuário da necessidade de possuir conhecimento técnico sobre o assunto.
C68: 2- Em nenhuma hipótese, qualquer indicação de Indulto ou Comutação atingirá os crimes impeditivos.
C69: 3- Indicação de Indulto no Art. 9º, incisos I, II, XIV, XV e no Art. 10 não alcança os crimes cometidos com violência ou grave ameaça.
...

Sheet Valid_dados
A1: Anos | C1: Meses | E1: Dias | H1: S/N | J1: SEXO | L1: S/N/NA | N1: F/AS/A | P1: TEMPO egressa | R1: TEMPO monitoração | T1: saída temporária | V1: TRABALHO EXTERNO | X1: Estudo
A2: 0 | C2: 0 | E2: 0 | H2: SIM | J2: FEMININO | L2: SIM | N2: FECHADO | P2: NÃO | R2: NÃO | T2: NÃO | V2: NÃO | X2: NÃO
A3: 1 | C3: 1 | E3: 1 | H3: NÃO | J3: MASCULINO | L3: NÃO | N3: SEMIABERTO | P3: HÁ MENOS DE 01 ANO | R3: HÁ MENOS DE 01 ANO E 06 MESES | T3: ATÉ 02 | V3: ATÉ 06 MESES | X3: MENOS DE 12 MESES
A4: 2 | C4: 2 | E4: 2 | L4: NÃO SE APLICA | N4: ABERTO | P4: ENTRE 01 E 02 ANOS | R4: ENTRE 01 ANO E 06 MESES E 03 ANOS | T4: 03 OU 04 | V4: DE 06 À 12 MESES | X4: MAIS DE 12 MESES NOS ÚLTIMOS 3 ANOS
A5: 3 | C5: 3 | E5: 3 | P5: HÁ MAIS DE 02 ANOS | R5: HÁ MAIS DE 03 ANOS | T5: 05 OU MAIS | V5: ACIMA DE 12 MESES | X5: MAIS DE 18 MESES NOS ÚLTIMOS 5 ANOS
A6: 4 | C6: 4 | E6: 4
A7: 5 | C7: 5 | E7: 5
A8: 6 | C8: 6 | E8: 6 | U8: mínimo, doze meses, nos três anos anteriores, se não reincidentes, ou dezoito meses, nos cinco anos anteriores, se reincidentes
A9: 7 | C9: 7 | E9: 7
A10: 8 | C10: 8 | E10: 8
A11: 9 | C11: 9 | E11: 9
A12: 10 | C12: 10 | E12: 10
A13: 11 | C13: 11 | E13: 11
A14: 12 | E14: 12
A15: 13 | E15: 13
A16: 14 | E16: 14
A17: 15 | E17: 15
A18: 16 | E18: 16
A19: 17 | E19: 17
A20: 18 | E20: 18
A21: 19 | E21: 19
A22: 20 | E22: 20
A23: 21 | E23: 21
A24: 22 | E24: 22
A25: 23 | E25: 23
... A32: 30 | E32: 30
A33: 31
A34: 32
A35: 33
A36: 34
A37: 35
A38: 36
A39: 37
A40: 38
A41: 39
A42: 40
A43: 41
A44: 42
... A302: 300

Sheet Somar tempo - Calcular Data
B4: SOMAR TEMPO DE PENA
B5: Anos | C5: Meses | D5: Dias | G5: Total de Dias
G6: =D6+(C6*30)+(B6*360) -> 0
G7: =D7+(C7*30)+(B7*360) -> 0
G8: =D8+(C8*30)+(B8*360) -> 0
G9: =D9+(C9*30)+(B9*360) -> 0
G10: =D10+(C10*30)+(B10*360) -> 0
B11: =IF(SUM(D6:D10)<=30,IF(SUM(C6:C10)<=11,SUM(B6:B10),IF(SUM(C6:C10)<=23,SUM(B6:B10)+1,IF(SUM(C6:C10)<=35,SUM(B6:B10)+2,SUM(B6:B10)+3))), IF(SUM(D6:D10)<=60,IF(SUM(C6:C10)+1<=11,SUM(B6:B10),IF(SUM(C6:C10)+1<=23,SUM(B6:B10)+1,IF(SUM(C6:C10)+1<=35,SUM(B6:B10)+2,SUM(B6:B10)+3))), IF(SUM(D6:D10)<=90,IF(SUM(C6:C10)+2<=11,SUM(B6:B10),IF(SUM(C6:C10)+2<=23,SUM(B6:B10)+1,IF(SUM(C6:C10)+2<=35,SUM(B6:B10)+2,SUM(B6:B10)+3))), "ERRO"))) -> 0 | C11: =IF(SUM(D6:D10)<=30,(IF(SUM(C6:C10)<=11,SUM(C6:C10),IF(SUM(C6:C10)<=23,SUM(C6:C10)-12,IF(SUM(C6:C10)<=35,SUM(C6:C10)-24,SUM(C6:C10)-36)))), IF(SUM(D6:D10)<=60,(IF(SUM(C6:C10)+1<=11,SUM(C6:C10)+1,IF(SUM(C6:C10)+1<=23,SUM(C6:C10)+1-12,IF(SUM(C6:C10)+1<=35,SUM(C6:C10)+1-24,SUM(C6:C10)+1-36)))), IF(SUM(D6:D10)<=90,(IF(SUM(C6:C10)+2<=11,SUM(C6:C10)+2,IF(SUM(C6:C10)+2<=23,SUM(C6:C10)+2-12,IF(SUM(C6:C10)+2<=35,SUM(C6:C10)+2-24,SUM(C6:C10)+2-36)))),"ERRO"))) -> 0 | D11: =IF(SUM(D6:D10)<=30,SUM(D6:D10), IF(SUM(D6:D10)<=60,SUM(D6:D10)-30, IF(SUM(D6:D10)<=90,SUM(D6:D10)-60, "ERRO"))) -> 0 | G11: =SUM(G6:G10) -> 0
B14: DIMINUIR TEMPO DE PENA
B15: Anos | C15: Meses | D15: Dias | G15: Total de Dias
G16: =D16+(C16*30)+(B16*360) -> 0 | I16: =G16/360 -> 0 | J16: =((G16/360)-ROUNDDOWN((G16/360),0))*12 -> 0 | K16: =((((G16/360)-ROUNDDOWN((G16/360),0))*12)-ROUNDDOWN((((G16/360)-ROUNDDOWN((G16/360),0))*12),0))*30 -> 0
G17: =D17+(C17*30)+(B17*360) -> 0 | I17: =G17/360 -> 0 | J17: =((G17/360)-ROUNDDOWN((G17/360),0))*12 -> 0 | K17: =((((G17/360)-ROUNDDOWN((G17/360),0))*12)-ROUNDDOWN((((G17/360)-ROUNDDOWN((G17/360),0))*12),0))*30 -> 0
B18: =""&ROUNDDOWN(I18,0)&" anos "&ROUNDDOWN(J18,0)&" meses "&ROUNDUP(K18,0)&" dias" -> 0 anos 0 meses 0 dias | G18: =G16-G17 -> 0 | I18: =G18/360 -> 0 | J18: =((G18/360)-ROUNDDOWN((G18/360),0))*12 -> 0 | K18: =((((G18/360)-ROUNDDOWN((G18/360),0))*12)-ROUNDDOWN((((G18/360)-ROUNDDOWN((G18/360),0))*12),0))*30 -> 0
B21: CALCULAR TEMPO DE PENA A PARTIR DE UMA DATA
B22: Total da Pena | E22: Pena Imposta 360 | F22: Pena Imposta 365 | G22: Data início | H22: Data Fim
B23: Anos | C23: Meses | D23: Dias
E24: =D24+(C24*30)+(B24*360) -> 0 | F24: =D24+(C24*30)+(B24*365) -> 0 | G24: 46016 | H24: =G24+((F24/365)*365.25) -> 46016
B27: CALCULAR TEMPO DE PENA ENTRE DATAS
B28: Data início | C28: Data Fim | D28: Período | F28: Tempo
D30: =" "&DATEDIF(0,F30,"y")&" anos "&DATEDIF(0,F30,"ym")&" meses "&DATEDIF(0,F30,"md")&" dias" -> 0 anos 0 meses 0 dias | F30: =C30-B30 -> 0
